ERROR 2025-01-21 08:35:27,847 log 8903 126997667776192 Internal Server Error: /system/register/
Traceback (most recent call last):
  File "/home/i-castorosa-098/Desktop/voice_auth_system/.venv/lib/python3.12/site-packages/django/template/base.py", line 505, in parse
    compile_func = self.tags[command]
                   ~~~~~~~~~^^^^^^^^^
KeyError: 'static'

During handling of the above exception, another exception occurred:

Traceback (most recent call last):
  File "/home/i-castorosa-098/Desktop/voice_auth_system/.venv/lib/python3.12/site-packages/django/core/handlers/exception.py", line 55, in inner
    response = get_response(request)
               ^^^^^^^^^^^^^^^^^^^^^
  File "/home/i-castorosa-098/Desktop/voice_auth_system/.venv/lib/python3.12/site-packages/django/core/handlers/base.py", line 220, in _get_response
    response = response.render()
               ^^^^^^^^^^^^^^^^^
  File "/home/i-castorosa-098/Desktop/voice_auth_system/.venv/lib/python3.12/site-packages/django/template/response.py", line 114, in render
    self.content = self.rendered_content
                   ^^^^^^^^^^^^^^^^^^^^^
  File "/home/i-castorosa-098/Desktop/voice_auth_system/.venv/lib/python3.12/site-packages/django/template/response.py", line 90, in rendered_content
    template = self.resolve_template(self.template_name)
               ^^^^^^^^^^^^^^^^^^^^^^^^^^^^^^^^^^^^^^^^^
  File "/home/i-castorosa-098/Desktop/voice_auth_system/.venv/lib/python3.12/site-packages/django/template/response.py", line 72, in resolve_template
    return select_template(template, using=self.using)
           ^^^^^^^^^^^^^^^^^^^^^^^^^^^^^^^^^^^^^^^^^^^
  File "/home/i-castorosa-098/Desktop/voice_auth_system/.venv/lib/python3.12/site-packages/django/template/loader.py", line 42, in select_template
    return engine.get_template(template_name)
           ^^^^^^^^^^^^^^^^^^^^^^^^^^^^^^^^^^
  File "/home/i-castorosa-098/Desktop/voice_auth_system/.venv/lib/python3.12/site-packages/django/template/backends/django.py", line 33, in get_template
    return Template(self.engine.get_template(template_name), self)
                    ^^^^^^^^^^^^^^^^^^^^^^^^^^^^^^^^^^^^^^^
  File "/home/i-castorosa-098/Desktop/voice_auth_system/.venv/lib/python3.12/site-packages/django/template/engine.py", line 175, in get_template
    template, origin = self.find_template(template_name)
                       ^^^^^^^^^^^^^^^^^^^^^^^^^^^^^^^^^
  File "/home/i-castorosa-098/Desktop/voice_auth_system/.venv/lib/python3.12/site-packages/django/template/engine.py", line 157, in find_template
    template = loader.get_template(name, skip=skip)
               ^^^^^^^^^^^^^^^^^^^^^^^^^^^^^^^^^^^^
  File "/home/i-castorosa-098/Desktop/voice_auth_system/.venv/lib/python3.12/site-packages/django/template/loaders/cached.py", line 57, in get_template
    template = super().get_template(template_name, skip)
               ^^^^^^^^^^^^^^^^^^^^^^^^^^^^^^^^^^^^^^^^^
  File "/home/i-castorosa-098/Desktop/voice_auth_system/.venv/lib/python3.12/site-packages/django/template/loaders/base.py", line 28, in get_template
    return Template(
           ^^^^^^^^^
  File "/home/i-castorosa-098/Desktop/voice_auth_system/.venv/lib/python3.12/site-packages/django/template/base.py", line 154, in __init__
    self.nodelist = self.compile_nodelist()
                    ^^^^^^^^^^^^^^^^^^^^^^^
  File "/home/i-castorosa-098/Desktop/voice_auth_system/.venv/lib/python3.12/site-packages/django/template/base.py", line 200, in compile_nodelist
    return parser.parse()
           ^^^^^^^^^^^^^^
  File "/home/i-castorosa-098/Desktop/voice_auth_system/.venv/lib/python3.12/site-packages/django/template/base.py", line 507, in parse
    self.invalid_block_tag(token, command, parse_until)
  File "/home/i-castorosa-098/Desktop/voice_auth_system/.venv/lib/python3.12/site-packages/django/template/base.py", line 568, in invalid_block_tag
    raise self.error(
django.template.exceptions.TemplateSyntaxError: Invalid block tag on line 10: 'static'. Did you forget to register or load this tag?
ERROR 2025-01-21 08:35:27,850 basehttp 8903 126997667776192 "GET /system/register/ HTTP/1.1" 500 146841
ERROR 2025-01-21 08:36:40,586 log 8903 126997667776192 Internal Server Error: /system/register/
Traceback (most recent call last):
  File "/home/i-castorosa-098/Desktop/voice_auth_system/.venv/lib/python3.12/site-packages/django/template/base.py", line 505, in parse
    compile_func = self.tags[command]
                   ~~~~~~~~~^^^^^^^^^
KeyError: 'static'

During handling of the above exception, another exception occurred:

Traceback (most recent call last):
  File "/home/i-castorosa-098/Desktop/voice_auth_system/.venv/lib/python3.12/site-packages/django/core/handlers/exception.py", line 55, in inner
    response = get_response(request)
               ^^^^^^^^^^^^^^^^^^^^^
  File "/home/i-castorosa-098/Desktop/voice_auth_system/.venv/lib/python3.12/site-packages/django/core/handlers/base.py", line 220, in _get_response
    response = response.render()
               ^^^^^^^^^^^^^^^^^
  File "/home/i-castorosa-098/Desktop/voice_auth_system/.venv/lib/python3.12/site-packages/django/template/response.py", line 114, in render
    self.content = self.rendered_content
                   ^^^^^^^^^^^^^^^^^^^^^
  File "/home/i-castorosa-098/Desktop/voice_auth_system/.venv/lib/python3.12/site-packages/django/template/response.py", line 90, in rendered_content
    template = self.resolve_template(self.template_name)
               ^^^^^^^^^^^^^^^^^^^^^^^^^^^^^^^^^^^^^^^^^
  File "/home/i-castorosa-098/Desktop/voice_auth_system/.venv/lib/python3.12/site-packages/django/template/response.py", line 72, in resolve_template
    return select_template(template, using=self.using)
           ^^^^^^^^^^^^^^^^^^^^^^^^^^^^^^^^^^^^^^^^^^^
  File "/home/i-castorosa-098/Desktop/voice_auth_system/.venv/lib/python3.12/site-packages/django/template/loader.py", line 42, in select_template
    return engine.get_template(template_name)
           ^^^^^^^^^^^^^^^^^^^^^^^^^^^^^^^^^^
  File "/home/i-castorosa-098/Desktop/voice_auth_system/.venv/lib/python3.12/site-packages/django/template/backends/django.py", line 33, in get_template
    return Template(self.engine.get_template(template_name), self)
                    ^^^^^^^^^^^^^^^^^^^^^^^^^^^^^^^^^^^^^^^
  File "/home/i-castorosa-098/Desktop/voice_auth_system/.venv/lib/python3.12/site-packages/django/template/engine.py", line 175, in get_template
    template, origin = self.find_template(template_name)
                       ^^^^^^^^^^^^^^^^^^^^^^^^^^^^^^^^^
  File "/home/i-castorosa-098/Desktop/voice_auth_system/.venv/lib/python3.12/site-packages/django/template/engine.py", line 157, in find_template
    template = loader.get_template(name, skip=skip)
               ^^^^^^^^^^^^^^^^^^^^^^^^^^^^^^^^^^^^
  File "/home/i-castorosa-098/Desktop/voice_auth_system/.venv/lib/python3.12/site-packages/django/template/loaders/cached.py", line 57, in get_template
    template = super().get_template(template_name, skip)
               ^^^^^^^^^^^^^^^^^^^^^^^^^^^^^^^^^^^^^^^^^
  File "/home/i-castorosa-098/Desktop/voice_auth_system/.venv/lib/python3.12/site-packages/django/template/loaders/base.py", line 28, in get_template
    return Template(
           ^^^^^^^^^
  File "/home/i-castorosa-098/Desktop/voice_auth_system/.venv/lib/python3.12/site-packages/django/template/base.py", line 154, in __init__
    self.nodelist = self.compile_nodelist()
                    ^^^^^^^^^^^^^^^^^^^^^^^
  File "/home/i-castorosa-098/Desktop/voice_auth_system/.venv/lib/python3.12/site-packages/django/template/base.py", line 200, in compile_nodelist
    return parser.parse()
           ^^^^^^^^^^^^^^
  File "/home/i-castorosa-098/Desktop/voice_auth_system/.venv/lib/python3.12/site-packages/django/template/base.py", line 507, in parse
    self.invalid_block_tag(token, command, parse_until)
  File "/home/i-castorosa-098/Desktop/voice_auth_system/.venv/lib/python3.12/site-packages/django/template/base.py", line 568, in invalid_block_tag
    raise self.error(
django.template.exceptions.TemplateSyntaxError: Invalid block tag on line 10: 'static'. Did you forget to register or load this tag?
ERROR 2025-01-21 08:36:40,587 basehttp 8903 126997667776192 "GET /system/register/ HTTP/1.1" 500 147035
ERROR 2025-01-21 08:47:48,832 log 9143 138011993966272 Internal Server Error: /system/register/
Traceback (most recent call last):
  File "/home/i-castorosa-098/Desktop/voice_auth_system/.venv/lib/python3.12/site-packages/django/core/handlers/exception.py", line 55, in inner
    response = get_response(request)
               ^^^^^^^^^^^^^^^^^^^^^
  File "/home/i-castorosa-098/Desktop/voice_auth_system/.venv/lib/python3.12/site-packages/django/core/handlers/base.py", line 220, in _get_response
    response = response.render()
               ^^^^^^^^^^^^^^^^^
  File "/home/i-castorosa-098/Desktop/voice_auth_system/.venv/lib/python3.12/site-packages/django/template/response.py", line 114, in render
    self.content = self.rendered_content
                   ^^^^^^^^^^^^^^^^^^^^^
  File "/home/i-castorosa-098/Desktop/voice_auth_system/.venv/lib/python3.12/site-packages/django/template/response.py", line 92, in rendered_content
    return template.render(context, self._request)
           ^^^^^^^^^^^^^^^^^^^^^^^^^^^^^^^^^^^^^^^
  File "/home/i-castorosa-098/Desktop/voice_auth_system/.venv/lib/python3.12/site-packages/django/template/backends/django.py", line 61, in render
    return self.template.render(context)
           ^^^^^^^^^^^^^^^^^^^^^^^^^^^^^
  File "/home/i-castorosa-098/Desktop/voice_auth_system/.venv/lib/python3.12/site-packages/django/template/base.py", line 173, in render
    with context.bind_template(self):
  File "/usr/lib/python3.12/contextlib.py", line 137, in __enter__
    return next(self.gen)
           ^^^^^^^^^^^^^^
  File "/home/i-castorosa-098/Desktop/voice_auth_system/.venv/lib/python3.12/site-packages/django/template/context.py", line 251, in bind_template
    processors = template.engine.template_context_processors + self._processors
                 ^^^^^^^^^^^^^^^^^^^^^^^^^^^^^^^^^^^^^^^^^^^
  File "/home/i-castorosa-098/Desktop/voice_auth_system/.venv/lib/python3.12/site-packages/django/utils/functional.py", line 57, in __get__
    res = instance.__dict__[self.name] = self.func(instance)
                                         ^^^^^^^^^^^^^^^^^^^
  File "/home/i-castorosa-098/Desktop/voice_auth_system/.venv/lib/python3.12/site-packages/django/template/engine.py", line 116, in template_context_processors
    return tuple(import_string(path) for path in context_processors)
           ^^^^^^^^^^^^^^^^^^^^^^^^^^^^^^^^^^^^^^^^^^^^^^^^^^^^^^^^^
  File "/home/i-castorosa-098/Desktop/voice_auth_system/.venv/lib/python3.12/site-packages/django/template/engine.py", line 116, in <genexpr>
    return tuple(import_string(path) for path in context_processors)
                 ^^^^^^^^^^^^^^^^^^^
  File "/home/i-castorosa-098/Desktop/voice_auth_system/.venv/lib/python3.12/site-packages/django/utils/module_loading.py", line 30, in import_string
    return cached_import(module_path, class_name)
           ^^^^^^^^^^^^^^^^^^^^^^^^^^^^^^^^^^^^^^
  File "/home/i-castorosa-098/Desktop/voice_auth_system/.venv/lib/python3.12/site-packages/django/utils/module_loading.py", line 15, in cached_import
    module = import_module(module_path)
             ^^^^^^^^^^^^^^^^^^^^^^^^^^
  File "/usr/lib/python3.12/importlib/__init__.py", line 90, in import_module
    return _bootstrap._gcd_import(name[level:], package, level)
           ^^^^^^^^^^^^^^^^^^^^^^^^^^^^^^^^^^^^^^^^^^^^^^^^^^^^
  File "<frozen importlib._bootstrap>", line 1387, in _gcd_import
  File "<frozen importlib._bootstrap>", line 1360, in _find_and_load
  File "<frozen importlib._bootstrap>", line 1331, in _find_and_load_unlocked
  File "<frozen importlib._bootstrap>", line 935, in _load_unlocked
  File "<frozen importlib._bootstrap_external>", line 995, in exec_module
  File "<frozen importlib._bootstrap>", line 488, in _call_with_frames_removed
  File "/home/i-castorosa-098/Desktop/voice_auth_system/.venv/lib/python3.12/site-packages/account/context_processors.py", line 2, in <module>
    from account.models import Account
  File "/home/i-castorosa-098/Desktop/voice_auth_system/.venv/lib/python3.12/site-packages/account/models.py", line 27, in <module>
    class Account(models.Model):
  File "/home/i-castorosa-098/Desktop/voice_auth_system/.venv/lib/python3.12/site-packages/django/db/models/base.py", line 134, in __new__
    raise RuntimeError(
RuntimeError: Model class account.models.Account doesn't declare an explicit app_label and isn't in an application in INSTALLED_APPS.
ERROR 2025-01-21 08:47:48,834 basehttp 9143 138011993966272 "GET /system/register/ HTTP/1.1" 500 219528
ERROR 2025-01-21 08:47:50,634 log 9143 138011993966272 Internal Server Error: /system/register/
Traceback (most recent call last):
  File "/home/i-castorosa-098/Desktop/voice_auth_system/.venv/lib/python3.12/site-packages/django/core/handlers/exception.py", line 55, in inner
    response = get_response(request)
               ^^^^^^^^^^^^^^^^^^^^^
  File "/home/i-castorosa-098/Desktop/voice_auth_system/.venv/lib/python3.12/site-packages/django/core/handlers/base.py", line 220, in _get_response
    response = response.render()
               ^^^^^^^^^^^^^^^^^
  File "/home/i-castorosa-098/Desktop/voice_auth_system/.venv/lib/python3.12/site-packages/django/template/response.py", line 114, in render
    self.content = self.rendered_content
                   ^^^^^^^^^^^^^^^^^^^^^
  File "/home/i-castorosa-098/Desktop/voice_auth_system/.venv/lib/python3.12/site-packages/django/template/response.py", line 92, in rendered_content
    return template.render(context, self._request)
           ^^^^^^^^^^^^^^^^^^^^^^^^^^^^^^^^^^^^^^^
  File "/home/i-castorosa-098/Desktop/voice_auth_system/.venv/lib/python3.12/site-packages/django/template/backends/django.py", line 61, in render
    return self.template.render(context)
           ^^^^^^^^^^^^^^^^^^^^^^^^^^^^^
  File "/home/i-castorosa-098/Desktop/voice_auth_system/.venv/lib/python3.12/site-packages/django/template/base.py", line 173, in render
    with context.bind_template(self):
  File "/usr/lib/python3.12/contextlib.py", line 137, in __enter__
    return next(self.gen)
           ^^^^^^^^^^^^^^
  File "/home/i-castorosa-098/Desktop/voice_auth_system/.venv/lib/python3.12/site-packages/django/template/context.py", line 251, in bind_template
    processors = template.engine.template_context_processors + self._processors
                 ^^^^^^^^^^^^^^^^^^^^^^^^^^^^^^^^^^^^^^^^^^^
  File "/home/i-castorosa-098/Desktop/voice_auth_system/.venv/lib/python3.12/site-packages/django/utils/functional.py", line 57, in __get__
    res = instance.__dict__[self.name] = self.func(instance)
                                         ^^^^^^^^^^^^^^^^^^^
  File "/home/i-castorosa-098/Desktop/voice_auth_system/.venv/lib/python3.12/site-packages/django/template/engine.py", line 116, in template_context_processors
    return tuple(import_string(path) for path in context_processors)
           ^^^^^^^^^^^^^^^^^^^^^^^^^^^^^^^^^^^^^^^^^^^^^^^^^^^^^^^^^
  File "/home/i-castorosa-098/Desktop/voice_auth_system/.venv/lib/python3.12/site-packages/django/template/engine.py", line 116, in <genexpr>
    return tuple(import_string(path) for path in context_processors)
                 ^^^^^^^^^^^^^^^^^^^
  File "/home/i-castorosa-098/Desktop/voice_auth_system/.venv/lib/python3.12/site-packages/django/utils/module_loading.py", line 30, in import_string
    return cached_import(module_path, class_name)
           ^^^^^^^^^^^^^^^^^^^^^^^^^^^^^^^^^^^^^^
  File "/home/i-castorosa-098/Desktop/voice_auth_system/.venv/lib/python3.12/site-packages/django/utils/module_loading.py", line 15, in cached_import
    module = import_module(module_path)
             ^^^^^^^^^^^^^^^^^^^^^^^^^^
  File "/usr/lib/python3.12/importlib/__init__.py", line 90, in import_module
    return _bootstrap._gcd_import(name[level:], package, level)
           ^^^^^^^^^^^^^^^^^^^^^^^^^^^^^^^^^^^^^^^^^^^^^^^^^^^^
  File "<frozen importlib._bootstrap>", line 1387, in _gcd_import
  File "<frozen importlib._bootstrap>", line 1360, in _find_and_load
  File "<frozen importlib._bootstrap>", line 1331, in _find_and_load_unlocked
  File "<frozen importlib._bootstrap>", line 935, in _load_unlocked
  File "<frozen importlib._bootstrap_external>", line 995, in exec_module
  File "<frozen importlib._bootstrap>", line 488, in _call_with_frames_removed
  File "/home/i-castorosa-098/Desktop/voice_auth_system/.venv/lib/python3.12/site-packages/account/context_processors.py", line 2, in <module>
    from account.models import Account
  File "/home/i-castorosa-098/Desktop/voice_auth_system/.venv/lib/python3.12/site-packages/account/models.py", line 27, in <module>
    class Account(models.Model):
  File "/home/i-castorosa-098/Desktop/voice_auth_system/.venv/lib/python3.12/site-packages/django/db/models/base.py", line 134, in __new__
    raise RuntimeError(
RuntimeError: Model class account.models.Account doesn't declare an explicit app_label and isn't in an application in INSTALLED_APPS.
ERROR 2025-01-21 08:47:50,636 basehttp 9143 138011993966272 "GET /system/register/ HTTP/1.1" 500 219528
ERROR 2025-01-21 09:01:11,225 log 9419 138277323540160 Internal Server Error: /system/register/
Traceback (most recent call last):
  File "/home/i-castorosa-098/Desktop/voice_auth_system/.venv/lib/python3.12/site-packages/django/core/handlers/exception.py", line 55, in inner
    response = get_response(request)
               ^^^^^^^^^^^^^^^^^^^^^
  File "/home/i-castorosa-098/Desktop/voice_auth_system/.venv/lib/python3.12/site-packages/django/core/handlers/base.py", line 220, in _get_response
    response = response.render()
               ^^^^^^^^^^^^^^^^^
  File "/home/i-castorosa-098/Desktop/voice_auth_system/.venv/lib/python3.12/site-packages/django/template/response.py", line 114, in render
    self.content = self.rendered_content
                   ^^^^^^^^^^^^^^^^^^^^^
  File "/home/i-castorosa-098/Desktop/voice_auth_system/.venv/lib/python3.12/site-packages/django/template/response.py", line 92, in rendered_content
    return template.render(context, self._request)
           ^^^^^^^^^^^^^^^^^^^^^^^^^^^^^^^^^^^^^^^
  File "/home/i-castorosa-098/Desktop/voice_auth_system/.venv/lib/python3.12/site-packages/django/template/backends/django.py", line 61, in render
    return self.template.render(context)
           ^^^^^^^^^^^^^^^^^^^^^^^^^^^^^
  File "/home/i-castorosa-098/Desktop/voice_auth_system/.venv/lib/python3.12/site-packages/django/template/base.py", line 173, in render
    with context.bind_template(self):
  File "/usr/lib/python3.12/contextlib.py", line 137, in __enter__
    return next(self.gen)
           ^^^^^^^^^^^^^^
  File "/home/i-castorosa-098/Desktop/voice_auth_system/.venv/lib/python3.12/site-packages/django/template/context.py", line 251, in bind_template
    processors = template.engine.template_context_processors + self._processors
                 ^^^^^^^^^^^^^^^^^^^^^^^^^^^^^^^^^^^^^^^^^^^
  File "/home/i-castorosa-098/Desktop/voice_auth_system/.venv/lib/python3.12/site-packages/django/utils/functional.py", line 57, in __get__
    res = instance.__dict__[self.name] = self.func(instance)
                                         ^^^^^^^^^^^^^^^^^^^
  File "/home/i-castorosa-098/Desktop/voice_auth_system/.venv/lib/python3.12/site-packages/django/template/engine.py", line 116, in template_context_processors
    return tuple(import_string(path) for path in context_processors)
           ^^^^^^^^^^^^^^^^^^^^^^^^^^^^^^^^^^^^^^^^^^^^^^^^^^^^^^^^^
  File "/home/i-castorosa-098/Desktop/voice_auth_system/.venv/lib/python3.12/site-packages/django/template/engine.py", line 116, in <genexpr>
    return tuple(import_string(path) for path in context_processors)
                 ^^^^^^^^^^^^^^^^^^^
  File "/home/i-castorosa-098/Desktop/voice_auth_system/.venv/lib/python3.12/site-packages/django/utils/module_loading.py", line 30, in import_string
    return cached_import(module_path, class_name)
           ^^^^^^^^^^^^^^^^^^^^^^^^^^^^^^^^^^^^^^
  File "/home/i-castorosa-098/Desktop/voice_auth_system/.venv/lib/python3.12/site-packages/django/utils/module_loading.py", line 15, in cached_import
    module = import_module(module_path)
             ^^^^^^^^^^^^^^^^^^^^^^^^^^
  File "/usr/lib/python3.12/importlib/__init__.py", line 90, in import_module
    return _bootstrap._gcd_import(name[level:], package, level)
           ^^^^^^^^^^^^^^^^^^^^^^^^^^^^^^^^^^^^^^^^^^^^^^^^^^^^
  File "<frozen importlib._bootstrap>", line 1387, in _gcd_import
  File "<frozen importlib._bootstrap>", line 1360, in _find_and_load
  File "<frozen importlib._bootstrap>", line 1331, in _find_and_load_unlocked
  File "<frozen importlib._bootstrap>", line 935, in _load_unlocked
  File "<frozen importlib._bootstrap_external>", line 995, in exec_module
  File "<frozen importlib._bootstrap>", line 488, in _call_with_frames_removed
  File "/home/i-castorosa-098/Desktop/voice_auth_system/.venv/lib/python3.12/site-packages/account/context_processors.py", line 2, in <module>
    from account.models import Account
  File "/home/i-castorosa-098/Desktop/voice_auth_system/.venv/lib/python3.12/site-packages/account/models.py", line 27, in <module>
    class Account(models.Model):
  File "/home/i-castorosa-098/Desktop/voice_auth_system/.venv/lib/python3.12/site-packages/django/db/models/base.py", line 134, in __new__
    raise RuntimeError(
RuntimeError: Model class account.models.Account doesn't declare an explicit app_label and isn't in an application in INSTALLED_APPS.
ERROR 2025-01-21 09:01:11,229 basehttp 9419 138277323540160 "GET /system/register/ HTTP/1.1" 500 219528
ERROR 2025-01-21 09:01:17,183 log 9419 138277323540160 Internal Server Error: /system/register/
Traceback (most recent call last):
  File "/home/i-castorosa-098/Desktop/voice_auth_system/.venv/lib/python3.12/site-packages/django/core/handlers/exception.py", line 55, in inner
    response = get_response(request)
               ^^^^^^^^^^^^^^^^^^^^^
  File "/home/i-castorosa-098/Desktop/voice_auth_system/.venv/lib/python3.12/site-packages/django/core/handlers/base.py", line 220, in _get_response
    response = response.render()
               ^^^^^^^^^^^^^^^^^
  File "/home/i-castorosa-098/Desktop/voice_auth_system/.venv/lib/python3.12/site-packages/django/template/response.py", line 114, in render
    self.content = self.rendered_content
                   ^^^^^^^^^^^^^^^^^^^^^
  File "/home/i-castorosa-098/Desktop/voice_auth_system/.venv/lib/python3.12/site-packages/django/template/response.py", line 92, in rendered_content
    return template.render(context, self._request)
           ^^^^^^^^^^^^^^^^^^^^^^^^^^^^^^^^^^^^^^^
  File "/home/i-castorosa-098/Desktop/voice_auth_system/.venv/lib/python3.12/site-packages/django/template/backends/django.py", line 61, in render
    return self.template.render(context)
           ^^^^^^^^^^^^^^^^^^^^^^^^^^^^^
  File "/home/i-castorosa-098/Desktop/voice_auth_system/.venv/lib/python3.12/site-packages/django/template/base.py", line 173, in render
    with context.bind_template(self):
  File "/usr/lib/python3.12/contextlib.py", line 137, in __enter__
    return next(self.gen)
           ^^^^^^^^^^^^^^
  File "/home/i-castorosa-098/Desktop/voice_auth_system/.venv/lib/python3.12/site-packages/django/template/context.py", line 251, in bind_template
    processors = template.engine.template_context_processors + self._processors
                 ^^^^^^^^^^^^^^^^^^^^^^^^^^^^^^^^^^^^^^^^^^^
  File "/home/i-castorosa-098/Desktop/voice_auth_system/.venv/lib/python3.12/site-packages/django/utils/functional.py", line 57, in __get__
    res = instance.__dict__[self.name] = self.func(instance)
                                         ^^^^^^^^^^^^^^^^^^^
  File "/home/i-castorosa-098/Desktop/voice_auth_system/.venv/lib/python3.12/site-packages/django/template/engine.py", line 116, in template_context_processors
    return tuple(import_string(path) for path in context_processors)
           ^^^^^^^^^^^^^^^^^^^^^^^^^^^^^^^^^^^^^^^^^^^^^^^^^^^^^^^^^
  File "/home/i-castorosa-098/Desktop/voice_auth_system/.venv/lib/python3.12/site-packages/django/template/engine.py", line 116, in <genexpr>
    return tuple(import_string(path) for path in context_processors)
                 ^^^^^^^^^^^^^^^^^^^
  File "/home/i-castorosa-098/Desktop/voice_auth_system/.venv/lib/python3.12/site-packages/django/utils/module_loading.py", line 30, in import_string
    return cached_import(module_path, class_name)
           ^^^^^^^^^^^^^^^^^^^^^^^^^^^^^^^^^^^^^^
  File "/home/i-castorosa-098/Desktop/voice_auth_system/.venv/lib/python3.12/site-packages/django/utils/module_loading.py", line 15, in cached_import
    module = import_module(module_path)
             ^^^^^^^^^^^^^^^^^^^^^^^^^^
  File "/usr/lib/python3.12/importlib/__init__.py", line 90, in import_module
    return _bootstrap._gcd_import(name[level:], package, level)
           ^^^^^^^^^^^^^^^^^^^^^^^^^^^^^^^^^^^^^^^^^^^^^^^^^^^^
  File "<frozen importlib._bootstrap>", line 1387, in _gcd_import
  File "<frozen importlib._bootstrap>", line 1360, in _find_and_load
  File "<frozen importlib._bootstrap>", line 1331, in _find_and_load_unlocked
  File "<frozen importlib._bootstrap>", line 935, in _load_unlocked
  File "<frozen importlib._bootstrap_external>", line 995, in exec_module
  File "<frozen importlib._bootstrap>", line 488, in _call_with_frames_removed
  File "/home/i-castorosa-098/Desktop/voice_auth_system/.venv/lib/python3.12/site-packages/account/context_processors.py", line 2, in <module>
    from account.models import Account
  File "/home/i-castorosa-098/Desktop/voice_auth_system/.venv/lib/python3.12/site-packages/account/models.py", line 27, in <module>
    class Account(models.Model):
  File "/home/i-castorosa-098/Desktop/voice_auth_system/.venv/lib/python3.12/site-packages/django/db/models/base.py", line 134, in __new__
    raise RuntimeError(
RuntimeError: Model class account.models.Account doesn't declare an explicit app_label and isn't in an application in INSTALLED_APPS.
ERROR 2025-01-21 09:01:17,185 basehttp 9419 138277323540160 "GET /system/register/ HTTP/1.1" 500 219528
ERROR 2025-01-21 09:01:23,976 log 9568 126652801615552 Internal Server Error: /system/register/
Traceback (most recent call last):
  File "/home/i-castorosa-098/Desktop/voice_auth_system/.venv/lib/python3.12/site-packages/django/core/handlers/exception.py", line 55, in inner
    response = get_response(request)
               ^^^^^^^^^^^^^^^^^^^^^
  File "/home/i-castorosa-098/Desktop/voice_auth_system/.venv/lib/python3.12/site-packages/django/core/handlers/base.py", line 220, in _get_response
    response = response.render()
               ^^^^^^^^^^^^^^^^^
  File "/home/i-castorosa-098/Desktop/voice_auth_system/.venv/lib/python3.12/site-packages/django/template/response.py", line 114, in render
    self.content = self.rendered_content
                   ^^^^^^^^^^^^^^^^^^^^^
  File "/home/i-castorosa-098/Desktop/voice_auth_system/.venv/lib/python3.12/site-packages/django/template/response.py", line 92, in rendered_content
    return template.render(context, self._request)
           ^^^^^^^^^^^^^^^^^^^^^^^^^^^^^^^^^^^^^^^
  File "/home/i-castorosa-098/Desktop/voice_auth_system/.venv/lib/python3.12/site-packages/django/template/backends/django.py", line 61, in render
    return self.template.render(context)
           ^^^^^^^^^^^^^^^^^^^^^^^^^^^^^
  File "/home/i-castorosa-098/Desktop/voice_auth_system/.venv/lib/python3.12/site-packages/django/template/base.py", line 175, in render
    return self._render(context)
           ^^^^^^^^^^^^^^^^^^^^^
  File "/home/i-castorosa-098/Desktop/voice_auth_system/.venv/lib/python3.12/site-packages/django/template/base.py", line 167, in _render
    return self.nodelist.render(context)
           ^^^^^^^^^^^^^^^^^^^^^^^^^^^^^
  File "/home/i-castorosa-098/Desktop/voice_auth_system/.venv/lib/python3.12/site-packages/django/template/base.py", line 1005, in render
    return SafeString("".join([node.render_annotated(context) for node in self]))
                               ^^^^^^^^^^^^^^^^^^^^^^^^^^^^^^
  File "/home/i-castorosa-098/Desktop/voice_auth_system/.venv/lib/python3.12/site-packages/django/template/base.py", line 966, in render_annotated
    return self.render(context)
           ^^^^^^^^^^^^^^^^^^^^
  File "/home/i-castorosa-098/Desktop/voice_auth_system/.venv/lib/python3.12/site-packages/django/template/defaulttags.py", line 471, in render
    url = reverse(view_name, args=args, kwargs=kwargs, current_app=current_app)
          ^^^^^^^^^^^^^^^^^^^^^^^^^^^^^^^^^^^^^^^^^^^^^^^^^^^^^^^^^^^^^^^^^^^^^
  File "/home/i-castorosa-098/Desktop/voice_auth_system/.venv/lib/python3.12/site-packages/django/urls/base.py", line 88, in reverse
    return resolver._reverse_with_prefix(view, prefix, *args, **kwargs)
           ^^^^^^^^^^^^^^^^^^^^^^^^^^^^^^^^^^^^^^^^^^^^^^^^^^^^^^^^^^^^
  File "/home/i-castorosa-098/Desktop/voice_auth_system/.venv/lib/python3.12/site-packages/django/urls/resolvers.py", line 828, in _reverse_with_prefix
    raise NoReverseMatch(msg)
django.urls.exceptions.NoReverseMatch: Reverse for 'login' not found. 'login' is not a valid view function or pattern name.
ERROR 2025-01-21 09:01:23,977 basehttp 9568 126652801615552 "GET /system/register/ HTTP/1.1" 500 115506
ERROR 2025-01-21 09:01:25,108 log 9568 126652801615552 Internal Server Error: /system/register/
Traceback (most recent call last):
  File "/home/i-castorosa-098/Desktop/voice_auth_system/.venv/lib/python3.12/site-packages/django/core/handlers/exception.py", line 55, in inner
    response = get_response(request)
               ^^^^^^^^^^^^^^^^^^^^^
  File "/home/i-castorosa-098/Desktop/voice_auth_system/.venv/lib/python3.12/site-packages/django/core/handlers/base.py", line 220, in _get_response
    response = response.render()
               ^^^^^^^^^^^^^^^^^
  File "/home/i-castorosa-098/Desktop/voice_auth_system/.venv/lib/python3.12/site-packages/django/template/response.py", line 114, in render
    self.content = self.rendered_content
                   ^^^^^^^^^^^^^^^^^^^^^
  File "/home/i-castorosa-098/Desktop/voice_auth_system/.venv/lib/python3.12/site-packages/django/template/response.py", line 92, in rendered_content
    return template.render(context, self._request)
           ^^^^^^^^^^^^^^^^^^^^^^^^^^^^^^^^^^^^^^^
  File "/home/i-castorosa-098/Desktop/voice_auth_system/.venv/lib/python3.12/site-packages/django/template/backends/django.py", line 61, in render
    return self.template.render(context)
           ^^^^^^^^^^^^^^^^^^^^^^^^^^^^^
  File "/home/i-castorosa-098/Desktop/voice_auth_system/.venv/lib/python3.12/site-packages/django/template/base.py", line 175, in render
    return self._render(context)
           ^^^^^^^^^^^^^^^^^^^^^
  File "/home/i-castorosa-098/Desktop/voice_auth_system/.venv/lib/python3.12/site-packages/django/template/base.py", line 167, in _render
    return self.nodelist.render(context)
           ^^^^^^^^^^^^^^^^^^^^^^^^^^^^^
  File "/home/i-castorosa-098/Desktop/voice_auth_system/.venv/lib/python3.12/site-packages/django/template/base.py", line 1005, in render
    return SafeString("".join([node.render_annotated(context) for node in self]))
                               ^^^^^^^^^^^^^^^^^^^^^^^^^^^^^^
  File "/home/i-castorosa-098/Desktop/voice_auth_system/.venv/lib/python3.12/site-packages/django/template/base.py", line 966, in render_annotated
    return self.render(context)
           ^^^^^^^^^^^^^^^^^^^^
  File "/home/i-castorosa-098/Desktop/voice_auth_system/.venv/lib/python3.12/site-packages/django/template/defaulttags.py", line 471, in render
    url = reverse(view_name, args=args, kwargs=kwargs, current_app=current_app)
          ^^^^^^^^^^^^^^^^^^^^^^^^^^^^^^^^^^^^^^^^^^^^^^^^^^^^^^^^^^^^^^^^^^^^^
  File "/home/i-castorosa-098/Desktop/voice_auth_system/.venv/lib/python3.12/site-packages/django/urls/base.py", line 88, in reverse
    return resolver._reverse_with_prefix(view, prefix, *args, **kwargs)
           ^^^^^^^^^^^^^^^^^^^^^^^^^^^^^^^^^^^^^^^^^^^^^^^^^^^^^^^^^^^^
  File "/home/i-castorosa-098/Desktop/voice_auth_system/.venv/lib/python3.12/site-packages/django/urls/resolvers.py", line 828, in _reverse_with_prefix
    raise NoReverseMatch(msg)
django.urls.exceptions.NoReverseMatch: Reverse for 'login' not found. 'login' is not a valid view function or pattern name.
ERROR 2025-01-21 09:01:25,109 basehttp 9568 126652801615552 "GET /system/register/ HTTP/1.1" 500 115506
ERROR 2025-01-21 09:01:25,314 log 9568 126652801615552 Internal Server Error: /system/register/
Traceback (most recent call last):
  File "/home/i-castorosa-098/Desktop/voice_auth_system/.venv/lib/python3.12/site-packages/django/core/handlers/exception.py", line 55, in inner
    response = get_response(request)
               ^^^^^^^^^^^^^^^^^^^^^
  File "/home/i-castorosa-098/Desktop/voice_auth_system/.venv/lib/python3.12/site-packages/django/core/handlers/base.py", line 220, in _get_response
    response = response.render()
               ^^^^^^^^^^^^^^^^^
  File "/home/i-castorosa-098/Desktop/voice_auth_system/.venv/lib/python3.12/site-packages/django/template/response.py", line 114, in render
    self.content = self.rendered_content
                   ^^^^^^^^^^^^^^^^^^^^^
  File "/home/i-castorosa-098/Desktop/voice_auth_system/.venv/lib/python3.12/site-packages/django/template/response.py", line 92, in rendered_content
    return template.render(context, self._request)
           ^^^^^^^^^^^^^^^^^^^^^^^^^^^^^^^^^^^^^^^
  File "/home/i-castorosa-098/Desktop/voice_auth_system/.venv/lib/python3.12/site-packages/django/template/backends/django.py", line 61, in render
    return self.template.render(context)
           ^^^^^^^^^^^^^^^^^^^^^^^^^^^^^
  File "/home/i-castorosa-098/Desktop/voice_auth_system/.venv/lib/python3.12/site-packages/django/template/base.py", line 175, in render
    return self._render(context)
           ^^^^^^^^^^^^^^^^^^^^^
  File "/home/i-castorosa-098/Desktop/voice_auth_system/.venv/lib/python3.12/site-packages/django/template/base.py", line 167, in _render
    return self.nodelist.render(context)
           ^^^^^^^^^^^^^^^^^^^^^^^^^^^^^
  File "/home/i-castorosa-098/Desktop/voice_auth_system/.venv/lib/python3.12/site-packages/django/template/base.py", line 1005, in render
    return SafeString("".join([node.render_annotated(context) for node in self]))
                               ^^^^^^^^^^^^^^^^^^^^^^^^^^^^^^
  File "/home/i-castorosa-098/Desktop/voice_auth_system/.venv/lib/python3.12/site-packages/django/template/base.py", line 966, in render_annotated
    return self.render(context)
           ^^^^^^^^^^^^^^^^^^^^
  File "/home/i-castorosa-098/Desktop/voice_auth_system/.venv/lib/python3.12/site-packages/django/template/defaulttags.py", line 471, in render
    url = reverse(view_name, args=args, kwargs=kwargs, current_app=current_app)
          ^^^^^^^^^^^^^^^^^^^^^^^^^^^^^^^^^^^^^^^^^^^^^^^^^^^^^^^^^^^^^^^^^^^^^
  File "/home/i-castorosa-098/Desktop/voice_auth_system/.venv/lib/python3.12/site-packages/django/urls/base.py", line 88, in reverse
    return resolver._reverse_with_prefix(view, prefix, *args, **kwargs)
           ^^^^^^^^^^^^^^^^^^^^^^^^^^^^^^^^^^^^^^^^^^^^^^^^^^^^^^^^^^^^
  File "/home/i-castorosa-098/Desktop/voice_auth_system/.venv/lib/python3.12/site-packages/django/urls/resolvers.py", line 828, in _reverse_with_prefix
    raise NoReverseMatch(msg)
django.urls.exceptions.NoReverseMatch: Reverse for 'login' not found. 'login' is not a valid view function or pattern name.
ERROR 2025-01-21 09:01:25,316 basehttp 9568 126652801615552 "GET /system/register/ HTTP/1.1" 500 115506
